Workbook

Sheet thousand_movies_with_ratings
A1: id | B1: title | C1: duration_minutes | D1: mpa | E1: release_date | F1: imdb_rating | G1: imdb_votes | H1: TMDB_Score | I1: TMDB_Vote_Count | J1: metacritic_score | K1: RT_Tomatometer
A2: tt12017738 | B2: Three Minutes: A Lengthening | C2: 69 | D2: PG | E2: 44658 | F2: 7.3 | G2: 715 | H2: 7 | I2: 7 | J2: 88 | K2: 100
A3: tt28814949 | B3: Taylor Swift: The Eras Tour | C3: 169 | D3: PG-13 | E3: 45211 | F3: 8 | G3: 24000 | H3: 8.189 | I3: 514 | J3: 82 | K3: 98
A4: tt12672536 | B4: The Three Musketeers - Part I: D'Artagnan | C4: 121 | D4: Not Rated | E4: 45021 | F4: 6.7 | G4: 24000 | H4: 6.922 | I4: 1378 | J4: 79 | K4: 98
A5: tt13840536 | B5: It Ain't Over | C5: 99 | D5: PG | E5: 44723 | F5: 8.2 | G5: 1600 | H5: 7.1 | I5: 12 | J5: 79 | K5: 98
A6: tt14961016 | B6: I'm Still Here | C6: 137 | D6: PG-13 | E6: 45695 | F6: 8.4 | G6: 98000 | H6: 7.902 | I6: 1035 | J6: 85 | K6: 97
A7: tt26315142 | B7: Totem | C7: 95 | D7: Unrated | E7: 45405 | F7: 7 | G7: 3700 | H7: 6.833 | I7: 90 | J7: 91 | K7: 97
A8: tt30319503 | B8: Didi | C8: 93 | D8: R | E8: 45520 | F8: 7.3 | G8: 12000 | H8: 7.2 | I8: 193 | J8: 78 | K8: 96
A9: tt16428256 | B9: Suzume | C9: 122 | D9: PG | E9: 45030 | F9: 7.6 | G9: 52000 | H9: 7.887 | I9: 1701 | J9: 77 | K9: 96
A10: tt3915174 | B10: Puss in Boots: The Last Wish | C10: 102 | D10: PG | E10: 44916 | F10: 7.8 | G10: 201000 | H10: 8.201 | I10: 8729 | J10: 73 | K10: 95
A11: tt10638522 | B11: Talk to Me | C11: 95 | D11: R | E11: 45135 | F11: 7.1 | G11: 179000 | H11: 7.136 | I11: 3665 | J11: 76 | K11: 94
A12: tt11559472 | B12: Ali & Ava | C12: 95 | D12: Not Rated | E12: 44624 | F12: 6.7 | G12: 3300 | H12: 6.7 | I12: 64 | J12: 75 | K12: 94
A13: tt3447590 | B13: Matilda: The Musical | C13: 117 | D13: PG | E13: 44920 | F13: 7 | G13: 31000 | H13: 6.791 | I13: 809 | J13: 72 | K13: 93
... A43: tt8105234 | B43: Flamin' Hot | C43: 99 | D43: PG-13 | E43: 45086 | F43: 6.8 | G43: 19000 | H43: 7.949 | I43: 799 | J43: 58 | K43: 67
A44: tt4959750 | B44: 1992 | C44: 97 | D44: R | E44: 45534 | F44: 5.7 | G44: 2900 | H44: 6.858 | I44: 215 | J44: 44 | K44: 65
A45: tt4495098 | B45: Gran Turismo | C45: 134 | D45: PG-13 | E45: 45163 | F45: 7.1 | G45: 119000 | H45: 7.705 | I45: 3331 | J45: 48 | K45: 65
A46: tt14781036 | B46: Inside | C46: 105 | D46: R | E46: 45181 | F46: 5.5 | G46: 20000 | H46: 5.7 | I46: 514 | J46: 53 | K46: 62
A47: tt23638614 | B47: Unsung Hero | C47: 113 | D47: PG | E47: 45408 | F47: 7 | G47: 4900 | H47: 6.969 | I47: 80 | J47: 46 | K47: 61
A48: tt23149780 | B48: Eden | C48: 120 | D48: R | E48: 45750 | F48: 6.1 | G48: 819 | H48: 6.7 | I48: 615 | J48: 60 | K48: 58
A49: tt31050620 | B49: Inheritance | C49: 101 | D49: R | E49: 45681 | F49: 5.6 | G49: 1200 | H49: 6 | I49: 83 | J49: 55 | K49: 55
A50: tt15153532 | B50: Strays | C50: 93 | D50: R | E50: 45156 | F50: 6.3 | G50: 35000 | H50: 7.168 | I50: 992 | J50: 54 | K50: 54
A51: tt6898324 | B51: City of Dreams | C51: 114 | D51: R | E51: 45534 | F51: 6.8 | G51: 1100 | H51: 6.3 | I51: 14 | J51: 14 | K51: 50
A52: tt3359350 | B52: Road House | C52: 121 | D52: R | E52: 45372 | F52: 6.2 | G52: 166000 | H52: 6.923 | I52: 2944 | J52: 57 | K52: 50
A53: tt1001520 | B53: The Last Voyage of the Demeter | C53: 118 | D53: R | E53: 45149 | F53: 6.1 | G53: 62000 | H53: 6.751 | I53: 1903 | J53: 52 | K53: 50
A54: tt23330554 | B54: Winnie-the-Pooh: Blood and Honey 2 | C54: 93 | D54: Not Rated | E54: 45469 | F54: 4.7 | G54: 11000 | H54: 5.773 | I54: 465 | J54: 27 | K54: 47
A55: tt10245072 | B55: Salem's Lot | C55: 114 | D55: R | E55: 45568 | F55: 5.6 | G55: 33000 | H55: 6.01 | I55: 672 | J55: 47 | K55: 46
A56: tt10323676 | B56: The Contractor | C56: 103 | D56: R | E56: 44652 | F56: 5.8 | G56: 32000 | H56: 6.358 | I56: 1040 | J56: 52 | K56: 45
... A243: tt10236164 | B243: The Girl with the Needle | C243: 123 | D243: Unrated | E243: 45681 | F243: 7.5 | G243: 12000 | H243: 7.588 | I243: 345 | J243: 82 | K243: 92
A244: tt28082769 | B244: 46270 | C244: 95 | D244: R | E244: 45674 | F244: 7.1 | G244: 21000 | H244: 7.015 | I244: 540 | J244: 76 | K244: 92
A245: tt2347285 | B245: The Best Christmas Pageant Ever | C245: 99 | D245: PG | E245: 45604 | F245: 6.8 | G245: 6000 | H245: 6.919 | I245: 123 | J245: 60 | K245: 92
A246: tt28349451 | B246: The Shadow Strays | C246: 144 | D246: TV-MA | E246: 45582 | F246: 6.5 | G246: 9000 | H246: 7.2 | I246: 309 | J246: 73 | K246: 92
A247: tt32627540 | B247: Watchmen: Chapter I | C247: 83 | D247: R | E247: 45517 | F247: 7 | G247: 6300 | H247: 7.383 | I247: 222 | J247: 71 | K247: 92
A248: tt13231544 | B248: About Dry Grasses | C248: 197 | D248: Not Rated | E248: 45433 | F248: 7.7 | G248: 17000 | H248: 7.657 | I248: 162 | J248: 88 | K248: 92
A249: tt15239678 | B249: Dune: Part Two | C249: 166 | D249: PG-13 | E249: 45352 | F249: 8.5 | G249: 615000 | H249: 8.129 | I249: 7787 | J249: 79 | K249: 92
A250: tt14230458 | B250: Poor Things | C250: 141 | D250: R | E250: 45282 | F250: 7.8 | G250: 336000 | H250: 7.648 | I250: 5416 | J250: 88 | K250: 92
A251: tt27145269 | B251: Mr. Monk's Last Case: A Monk Movie | C251: 97 | D251: TV-PG | E251: 45268 | F251: 6.7 | G251: 11000 | H251: 6.9 | I251: 231 | J251: 65 | K251: 92
A252: tt21156390 | B252: The Starling Girl | C252: 117 | D252: R | E252: 45118 | F252: 6.7 | G252: 2800 | H252: 6.4 | I252: 75 | J252: 78 | K252: 92
A253: tt19500164 | B253: Nimona | C253: 101 | D253: PG | E253: 45107 | F253: 7.5 | G253: 56000 | H253: 7.9 | I253: 1358 | J253: 75 | K253: 92
A254: tt19623228 | B254: Godland | C254: 143 | D254: Unrated | E254: 45097 | F254: 7.1 | G254: 8500 | H254: 6.8 | I254: 197 | J254: 81 | K254: 92
A255: tt9883832 | B255: Moonage Daydream | C255: 135 | D255: PG-13 | E255: 45045 | F255: 7.6 | G255: 16000 | H255: 7.485 | I255: 263 | J255: 83 | K255: 92
...

Sheet Stats
B1: IMDB | C1: IMDB Votes | D1: TMDB | E1: TMDB Votes | F1: Metacritic | G1: Tomatometer
A2: Mean | B2: =AVERAGE(thousand_movies_with_ratings!F:F) -> 6.3105 | C2: =AVERAGE(thousand_movies_with_ratings!G:G) -> 50846.359 | D2: =AVERAGE(thousand_movies_with_ratings!H:H) -> 6.556368 | E2: =AVERAGE(thousand_movies_with_ratings!I:I) -> 1129.765 | F2: =AVERAGE(thousand_movies_with_ratings!J:J) -> 60.637 | G2: =AVERAGE(thousand_movies_with_ratings!K:K) -> 68.978 | I2: First Release Date | J2: 44603
A3: Median | B3: =MEDIAN(thousand_movies_with_ratings!F:F) -> 6.4 | C3: =MEDIAN(thousand_movies_with_ratings!G:G) -> 17000 | D3: =MEDIAN(thousand_movies_with_ratings!H:H) -> 6.6 | E3: =MEDIAN(thousand_movies_with_ratings!I:I) -> 483 | F3: =MEDIAN(thousand_movies_with_ratings!J:J) -> 61 | G3: =MEDIAN(thousand_movies_with_ratings!K:K) -> 76 | I3: Last Release Date | J3: 45898
A4: Std Dev | B4: =STDEV(thousand_movies_with_ratings!F:F) -> 0.89471798 | C4: =STDEV(thousand_movies_with_ratings!G:G) -> 89414.625 | D4: =STDEV(thousand_movies_with_ratings!H:H) -> 0.7410595 | E4: =STDEV(thousand_movies_with_ratings!I:I) -> 1694.6004 | F4: =STDEV(thousand_movies_with_ratings!J:J) -> 15.165395 | G4: =STDEV(thousand_movies_with_ratings!K:K) -> 24.242508
A5: Min | B5: =MIN(thousand_movies_with_ratings!F:F) -> 1.6 | C5: =MIN(thousand_movies_with_ratings!G:G) -> 388 | D5: =MIN(thousand_movies_with_ratings!H:H) -> 2.2 | E5: =MIN(thousand_movies_with_ratings!I:I) -> 5 | F5: =MIN(thousand_movies_with_ratings!J:J) -> 14 | G5: =MIN(thousand_movies_with_ratings!K:K) -> 0
A6: Max | B6: =MAX(thousand_movies_with_ratings!F:F) -> 8.6 | C6: =MAX(thousand_movies_with_ratings!G:G) -> 869000 | D6: =MAX(thousand_movies_with_ratings!H:H) -> 8.333 | E6: =MAX(thousand_movies_with_ratings!I:I) -> 13962 | F6: =MAX(thousand_movies_with_ratings!J:J) -> 95 | G6: =MAX(thousand_movies_with_ratings!K:K) -> 100

Sheet T-Tests
A1: IMDB and TMDB
A2: Metacritic and Tomatometer
A3: Votes and Votes?
A5: t-Test: Paired Two Sample for Means
B7: IMDB | C7: TMDB
A8: Mean | B8: 6.3105 | C8: 6.556368 | D8: =B8-C8 -> -0.245868
A9: Variance | B9: 0.80052027 | C9: 0.54916918
A10: Observations | B10: 1000 | C10: 1000
A11: Pearson Correlation | B11: 0.79214217
A12: Hypothesized Mean Difference | B12: 0
A13: df | B13: 999
A14: t Stat | B14: -14.213051
A15: P(T<=t) one-tail | B15: 3.4297512e-42
A16: t Critical one-tail | B16: 1.6463803
A17: P(T<=t) two-tail | B17: 6.8595025e-42
A18: t Critical two-tail | B18: 1.9623415
B22: Metacritic | C22: Rotten Tomatoes
A23: Mean | B23: 60.637 | C23: 68.978 | D23: =B23-C23 -> -8.341
A24: Variance | B24: 229.98922 | C24: 587.69922
A25: Observations | B25: 1000 | C25: 1000
A26: Pearson Correlation | B26: 0.87643863
A27: Hypothesized Mean Difference | B27: 0
A28: df | B28: 999
A29: t Stat | B29: -20.039369
A30: P(T<=t) one-tail | B30: 1.185606e-75
A31: t Critical one-tail | B31: 1.6463803
A32: P(T<=t) two-tail | B32: 2.3712121e-75
A33: t Critical two-tail | B33: 1.9623415

Sheet Review Count Ratio
A1: Review Ratio
A2: =thousand_movies_with_ratings!G2/thousand_movies_with_ratings!I2 -> 102.14286
A3: =thousand_movies_with_ratings!G3/thousand_movies_with_ratings!I3 -> 46.692607
A4: =thousand_movies_with_ratings!G4/thousand_movies_with_ratings!I4 -> 17.416546 | C4: IMDB Votes/TMDB Votes
A5: =thousand_movies_with_ratings!G5/thousand_movies_with_ratings!I5 -> 133.33333 | D5: Ratio | E5: Movie
A6: =thousand_movies_with_ratings!G6/thousand_movies_with_ratings!I6 -> 94.68599 | C6: Max | D6: =MAX(A:A) -> 1988.8889 | E6: Laal Singh Chaddha
A7: =thousand_movies_with_ratings!G7/thousand_movies_with_ratings!I7 -> 41.111111 | C7: Median | D7: =MEDIAN(A:A) -> 41.174112 | E7: "Nimona" && "Totem"
A8: =thousand_movies_with_ratings!G8/thousand_movies_with_ratings!I8 -> 62.176166 | C8: Min | D8: =MIN(A:A) -> 0.46693387 | E8: The Life of Chuck
A9: =thousand_movies_with_ratings!G9/thousand_movies_with_ratings!I9 -> 30.570253
A10: =thousand_movies_with_ratings!G10/thousand_movies_with_ratings!I10 -> 23.026693 | C10: Mean | D10: =AVERAGE(A:A) -> 48.323385 | E10: 48x Reviews on IMDB
A11: =thousand_movies_with_ratings!G11/thousand_movies_with_ratings!I11 -> 48.840382
A12: =thousand_movies_with_ratings!G12/thousand_movies_with_ratings!I12 -> 51.5625 | D12: 0.90458015 | E12: Death of a Unicorn
A13: =thousand_movies_with_ratings!G13/thousand_movies_with_ratings!I13 -> 38.318912
A14: =thousand_movies_with_ratings!G14/thousand_movies_with_ratings!I14 -> 66.006601
A15: =thousand_movies_with_ratings!G15/thousand_movies_with_ratings!I15 -> 57.098423
A16: =thousand_movies_with_ratings!G16/thousand_movies_with_ratings!I16 -> 68.712475
A17: =thousand_movies_with_ratings!G17/thousand_movies_with_ratings!I17 -> 51.333333
A18: =thousand_movies_with_ratings!G18/thousand_movies_with_ratings!I18 -> 41.533546
A19: =thousand_movies_with_ratings!G19/thousand_movies_with_ratings!I19 -> 53.571429
A20: =thousand_movies_with_ratings!G20/thousand_movies_with_ratings!I20 -> 17.184265
A21: =thousand_movies_with_ratings!G21/thousand_movies_with_ratings!I21 -> 46.391753
A22: =thousand_movies_with_ratings!G22/thousand_movies_with_ratings!I22 -> 37.096774
A23: =thousand_movies_with_ratings!G23/thousand_movies_with_ratings!I23 -> 19.266055
A24: =thousand_movies_with_ratings!G24/thousand_movies_with_ratings!I24 -> 14.782609
... A1001: =thousand_movies_with_ratings!G1001/thousand_movies_with_ratings!I1001 -> 5.6265985

Sheet Most_Loved
A1: id | B1: title | C1: duration_minutes | D1: mpa | E1: release_date | F1: imdb_rating | G1: imdb_votes | H1: TMDB_Score | I1: TMDB_Vote_Count | J1: metacritic_score | K1: RT_Tomatometer | M1: High Review Count and High Scores
A2: tt1630029 | B2: Avatar: The Way of Water | C2: 192 | D2: PG-13 | E2: 44911 | F2: 7.5 | G2: 530000 | H2: 7.593 | I2: 13962 | J2: 67 | K2: 76 | M2: Of 100 Highest Rated and 100 Highest Votes
A3: tt1877830 | B3: The Batman | C3: 176 | D3: PG-13 | E3: 44624 | F3: 7.8 | G3: 864000 | H3: 7.658 | I3: 11781 | J3: 72 | K3: 85
A4: tt15398776 | B4: Oppenheimer | C4: 180 | D4: R | E4: 45128 | F4: 8.3 | G4: 869000 | H4: 8 | I4: 11599 | J4: 90 | K4: 93
A5: tt1517268 | B5: Barbie | C5: 114 | D5: PG-13 | E5: 45128 | G5: 601000 | I5: 10964 | J5: 80 | K5: 88 | N5: Both | S5: IMDB Rating | T5: IMDB Votes | U5: TMDB Rating | V5: TMDB Votes
A6: tt1745960 | B6: Top Gun: Maverick | C6: 130 | D6: PG-13 | E6: 44708 | F6: 8.2 | G6: 764000 | H6: 8.152 | I6: 10763 | J6: 78 | K6: 96 | N6: tt9362722 | O6: Spider-Man: Across the Spider-Verse | P6: 140 | Q6: PG | R6: 45079 | S6: 8.5 | T6: 444000 | U6: 8.333 | V6: 8445
A7: tt6718170 | B7: The Super Mario Bros. Movie | C7: 92 | D7: PG | E7: 45021 | G7: 264000 | H7: 7.6 | I7: 10483 | J7: 46 | K7: 59 | N7: tt15239678 | O7: Dune: Part Two | P7: 166 | Q7: PG-13 | R7: 45352 | S7: 8.5 | T7: 615000 | U7: 8.129 | V7: 7787
A8: tt9419884 | B8: Doctor Strange in the Multiverse of Madness | C8: 126 | D8: PG-13 | E8: 44687 | G8: 510000 | I8: 10205 | J8: 60 | K8: 73 | N8: tt15398776 | O8: Oppenheimer | P8: 180 | Q8: R | R8: 45128 | S8: 8.3 | T8: 869000 | U8: 8 | V8: 11599
A9: tt3915174 | B9: Puss in Boots: The Last Wish | C9: 102 | D9: PG | E9: 44916 | F9: 7.8 | G9: 201000 | H9: 8.201 | I9: 8729 | J9: 73 | K9: 95 | N9: tt29623480 | O9: The Wild Robot | P9: 102 | Q9: PG | R9: 45562 | S9: 8.2 | T9: 154000 | U9: 8.307 | V9: 5900
A10: tt10648342 | B10: Thor: Love and Thunder | C10: 118 | D10: PG-13 | E10: 44750 | G10: 429000 | I10: 8479 | J10: 57 | K10: 63 | N10: tt1745960 | O10: Top Gun: Maverick | P10: 130 | Q10: PG-13 | R10: 44708 | S10: 8.2 | T10: 764000 | U10: 8.152 | V10: 10763
A11: tt6263850 | B11: Deadpool & Wolverine | C11: 128 | D11: R | E11: 45499 | F11: 7.6 | G11: 482000 | H11: 7.557 | I11: 8466 | J11: 56 | K11: 78 | N11: tt6791350 | O11: Guardians of the Galaxy Vol. 3 | P11: 150 | Q11: PG-13 | R11: 45051 | S11: 7.9 | T11: 422000 | U11: 7.924 | V11: 8180
A12: tt9362722 | B12: Spider-Man: Across the Spider-Verse | C12: 140 | D12: PG | E12: 45079 | F12: 8.5 | G12: 444000 | H12: 8.333 | I12: 8445 | J12: 86 | K12: 95 | N12: tt3915174 | O12: Puss in Boots: The Last Wish | P12: 102 | Q12: PG | R12: 44916 | S12: 7.8 | T12: 201000 | U12: 8.201 | V12: 8729
A13: tt6791350 | B13: Guardians of the Galaxy Vol. 3 | C13: 150 | D13: PG-13 | E13: 45051 | F13: 7.9 | G13: 422000 | H13: 7.924 | I13: 8180 | J13: 64 | K13: 82 | N13: tt16277242 | O13: Society of the Snow | P13: 144 | Q13: R | R13: 45295 | S13: 7.8 | T13: 160000 | U13: 7.976 | V13: 3461
A14: tt6710474 | B14: Everything Everywhere All at Once | C14: 139 | D14: R | E14: 44659 | F14: 7.8 | G14: 576000 | H14: 7.72 | I14: 7834 | J14: 81 | K14: 93 | N14: tt6710474 | O14: Everything Everywhere All at Once | P14: 139 | Q14: R | R14: 44659 | S14: 7.8 | T14: 576000 | U14: 7.72 | V14: 7834
A15: tt10366206 | B15: John Wick: Chapter 4 | C15: 169 | D15: R | E15: 45009 | F15: 7.6 | G15: 372000 | H15: 7.706 | I15: 7825 | J15: 78 | K15: 94 | N15: tt1016150 | O15: All Quiet on the Western Front | P15: 148 | Q15: R | R15: 44862 | S15: 7.8 | T15: 271000 | U15: 7.717 | V15: 4603 | X15: Rating | Y15: Count
A16: tt15239678 | B16: Dune: Part Two | C16: 166 | D16: PG-13 | E16: 45352 | F16: 8.5 | G16: 615000 | H16: 8.129 | I16: 7787 | J16: 79 | K16: 92 | N16: tt1877830 | O16: The Batman | P16: 176 | Q16: PG-13 | R16: 44624 | S16: 7.8 | T16: 864000 | U16: 7.658 | V16: 11781 | X16: R | Y16: =COUNTIF(Q:Q, "R") -> 17
A17: tt11866324 | B17: Prey | C17: 100 | D17: R | E17: 44778 | G17: 246000 | H17: 7.662 | I17: 7618 | J17: 71 | K17: 94 | N17: tt14230458 | O17: Poor Things | P17: 141 | Q17: R | R17: 45282 | S17: 7.8 | T17: 336000 | U17: 7.648 | V17: 5416 | X17: PG-13 | Y17: =COUNTIF(Q:Q, "PG-13") -> 11
A18: tt12593682 | B18: Bullet Train | C18: 127 | D18: R | E18: 44778 | G18: 487000 | I18: 7407 | J18: 49 | K18: 52 | N18: tt23289160 | O18: Godzilla Minus One | P18: 124 | Q18: PG-13 | R18: 45261 | S18: 7.7 | T18: 168000 | U18: 7.573 | V18: 3082 | X18: PG | Y18: =COUNTIF(Q:Q, "PG") -> 9
A19: tt9114286 | B19: Black Panther: Wakanda Forever | C19: 161 | D19: PG-13 | E19: 44876 | G19: 327000 | I19: 7385 | J19: 67 | K19: 84 | N19: tt13833688 | O19: The Whale | P19: 117 | Q19: R | R19: 44916 | S19: 7.6 | T19: 243000 | U19: 7.775 | V19: 4615
A20: tt8041270 | B20: Jurassic World: Dominion | C20: 147 | D20: PG-13 | E20: 44722 | G20: 221000 | I20: 6975 | J20: 38 | K20: 29 | N20: tt10366206 | O20: John Wick: Chapter 4 | P20: 169 | Q20: R | R20: 45009 | S20: 7.6 | T20: 372000 | U20: 7.706 | V20: 7825
A21: tt6443346 | B21: Black Adam | C21: 125 | D21: PG-13 | E21: 44855 | G21: 290000 | I21: 6952 | J21: 41 | K21: 39 | N21: tt6263850 | O21: Deadpool & Wolverine | P21: 128 | Q21: R | R21: 45499 | S21: 7.6 | T21: 482000 | U21: 7.557 | V21: 8466
A22: tt11564570 | B22: Glass Onion | C22: 139 | D22: PG-13 | E22: 44918 | G22: 473000 | I22: 6718 | J22: 81 | K22: 91 | N22: tt17009710 | O22: Anatomy of a Fall | P22: 151 | Q22: R | R22: 45373 | S22: 7.6 | T22: 172000 | U22: 7.524 | V22: 3230
A23: tt1464335 | B23: Uncharted | C23: 116 | D23: PG-13 | E23: 44610 | G23: 280000 | I23: 6703 | J23: 45 | K23: 41 | N23: tt9603212 | O23: Mission: Impossible - Dead Reckoning Part One | P23: 163 | Q23: PG-13 | R23: 45119 | S23: 7.6 | T23: 282000 | U23: 7.5 | V23: 5040
A24: tt22022452 | B24: Inside Out 2 | C24: 96 | D24: PG | E24: 45457 | F24: 7.5 | G24: 212000 | H24: 7.5 | I24: 6589 | J24: 73 | K24: 91 | N24: tt7405458 | O24: A Man Called Otto | P24: 126 | Q24: PG-13 | R24: 44939 | S24: 7.5 | T24: 190000 | U24: 7.751 | V24: 3532
A25: tt5433140 | B25: Fast X | C25: 141 | D25: PG-13 | E25: 45065 | I25: 6258 | J25: 56 | K25: 56 | N25: tt4873118 | O25: Guy Ritchie's the Covenant | P25: 123 | Q25: R | R25: 45037 | S25: 7.5 | T25: 187000 | U25: 7.716 | V25: 3117
A26: tt9764362 | B26: The Menu | C26: 107 | D26: R | E26: 44883 | G26: 448000 | I26: 6062 | J26: 71 | K26: 88 | N26: tt1630029 | O26: Avatar: The Way of Water | P26: 192 | Q26: PG-13 | R26: 44911 | S26: 7.5 | T26: 530000 | U26: 7.593 | V26: 13962
A27: tt29623480 | B27: The Wild Robot | C27: 102 | D27: PG | E27: 45562 | F27: 8.2 | G27: 154000 | H27: 8.307 | I27: 5900 | J27: 85 | K27: 97 | N27: tt22022452 | O27: Inside Out 2 | P27: 96 | Q27: PG | R27: 45457 | S27: 7.5 | T27: 212000 | U27: 7.5 | V27: 6589
A28: tt17526714 | B28: The Substance | C28: 141 | D28: R | E28: 45555 | G28: 284000 | I28: 5872 | J28: 78 | K28: 89
A29: tt12412888 | B29: Sonic the Hedgehog 2 | C29: 122 | D29: PG | E29: 44659 | I29: 5818 | J29: 47 | K29: 69 | N29: IMDB | S29: Rating | T29: Votes
A30: tt7144666 | B30: The Black Phone | C30: 103 | D30: R | E30: 44736 | G30: 224000 | H30: 7.528 | I30: 5758 | J30: 65 | K30: 81 | N30: tt12037194 | O30: Furiosa: A Mad Max Saga | P30: 148 | Q30: R | R30: 45436 | S30: 7.5 | T30: 281000
A31: tt10954600 | B31: Ant-Man and the Wasp: Quantumania | C31: 124 | D31: PG-13 | E31: 44974 | G31: 248000 | I31: 5747 | J31: 48 | K31: 46 | N31: tt5537002 | O31: Killers of the Flower Moon | P31: 206 | Q31: R | R31: 45219 | S31: 7.6 | T31: 279000
A32: tt8097030 | B32: Turning Red | C32: 100 | D32: PG | E32: 44631 | G32: 164000 | I32: 5741 | J32: 83 | K32: 95 | N32: tt11813216 | O32: The Banshees of Inisherin | P32: 114 | Q32: R | R32: 44869 | S32: 7.7 | T32: 276000
A33: tt14230458 | B33: Poor Things | C33: 141 | D33: R | E33: 45282 | F33: 7.8 | G33: 336000 | H33: 7.648 | I33: 5416 | J33: 88 | K33: 92 | N33: tt14849194 | O33: The Holdovers | P33: 133 | Q33: R | R33: 45240 | S33: 7.9 | T33: 197000
A34: tt15789038 | B34: Elemental | C34: 101 | D34: PG | E34: 45093 | G34: 148000 | H34: 7.578 | I34: 5237 | J34: 58 | K34: 73 | N34: tt8178634 | O34: RRR | P34: 187 | Q34: TV-MA | R34: 44645 | S34: 7.8 | T34: 177000
A35: tt5090568 | B35: Transformers: Rise of the Beasts | C35: 127 | D35: PG-13 | E35: 45086 | I35: 5222 | J35: 42 | K35: 51 | N35: tt28607951 | O35: Anora | P35: 139 | Q35: R | R35: 45604 | S35: 7.6 | T35: 162000
A36: tt4123432 | B36: Fantastic Beasts: The Secrets of Dumbledore | C36: 142 | D36: PG-13 | E36: 44666 | G36: 183000 | I36: 5046 | J36: 47 | K36: 46 | N36: tt13238346 | O36: Past Lives | P36: 105 | Q36: PG-13 | R36: 45100 | S36: 7.8 | T36: 149000
A37: tt9603212 | B37: Mission: Impossible - Dead Reckoning Part One | C37: 163 | D37: PG-13 | E37: 45119 | F37: 7.6 | G37: 282000 | H37: 7.5 | I37: 5040 | J37: 81 | K37: 96 | N37: tt1262426 | O37: Wicked | P37: 160 | Q37: PG | R37: 45618 | S37: 7.5 | T37: 147000
A38: tt11138512 | B38: The Northman | C38: 137 | D38: R | E38: 44673 | G38: 277000 | I38: 4967 | J38: 82 | K38: 90
A39: tt4589218 | B39: Five Nights at Freddy's | C39: 109 | D39: PG-13 | E39: 45226 | I39: 4959 | J39: 33 | K39: 33 | N39: TMDB | S39: Rating | T39: Votes
A40: tt0439572 | B40: The Flash | C40: 144 | D40: PG-13 | E40: 45093 | G40: 231000 | I40: 4925 | J40: 55 | K40: 63 | N40: tt6718170 | O40: The Super Mario Bros. Movie | P40: 92 | Q40: PG | R40: 45021 | S40: 7.6 | T40: 10483
...

Sheet Most Hated
A1: id | B1: title | C1: duration_minutes | D1: mpa | E1: release_date | F1: imdb_rating | G1: imdb_votes | H1: TMDB_Score | I1: TMDB_Vote_Count | J1: metacritic_score | K1: RT_Tomatometer | M1: High Review Count and Low Scores
A2: tt15398776 | B2: Oppenheimer | C2: 180 | D2: R | E2: 45128 | G2: 869000 | I2: 11599 | J2: 90 | K2: 93 | M2: Of 100 Lowest Rated and 100 Highest Votes
A3: tt1877830 | B3: The Batman | C3: 176 | D3: PG-13 | E3: 44624 | G3: 864000 | I3: 11781 | J3: 72 | K3: 85
A4: tt1745960 | B4: Top Gun: Maverick | C4: 130 | D4: PG-13 | E4: 44708 | G4: 764000 | I4: 10763 | J4: 78 | K4: 96
A5: tt15239678 | B5: Dune: Part Two | C5: 166 | D5: PG-13 | E5: 45352 | G5: 615000 | I5: 7787 | J5: 79 | K5: 92 | N5: IMDB | S5: Rating | T5: Votes
A6: tt1517268 | B6: Barbie | C6: 114 | D6: PG-13 | E6: 45128 | G6: 601000 | I6: 10964 | J6: 80 | K6: 88 | N6: tt5108870 | O6: Morbius | P6: 104 | Q6: PG-13 | R6: 44652 | S6: 5.1 | T6: 163000
A7: tt6710474 | B7: Everything Everywhere All at Once | C7: 139 | D7: R | E7: 44659 | G7: 576000 | I7: 7834 | J7: 81 | K7: 93 | N7: tt11315808 | O7: Joker: Folie Ã Deux | P7: 138 | Q7: R | R7: 45569 | S7: 5.2 | T7: 157000
A8: tt1630029 | B8: Avatar: The Way of Water | C8: 192 | D8: PG-13 | E8: 44911 | G8: 530000 | I8: 13962 | J8: 67 | K8: 76 | N8: tt6208148 | O8: Snow White | P8: 109 | Q8: PG | R8: 45737 | S8: 1.6 | T8: 152000
A9: tt9419884 | B9: Doctor Strange in the Multiverse of Madness | C9: 126 | D9: PG-13 | E9: 44687 | G9: 510000 | I9: 10205 | J9: 60 | K9: 73
A10: tt12593682 | B10: Bullet Train | C10: 127 | D10: R | E10: 44778 | G10: 487000 | I10: 7407 | J10: 49 | K10: 52 | N10: None for TMDB
A11: tt6263850 | B11: Deadpool & Wolverine | C11: 128 | D11: R | E11: 45499 | G11: 482000 | I11: 8466 | J11: 56 | K11: 78
A12: tt11564570 | B12: Glass Onion | C12: 139 | D12: PG-13 | E12: 44918 | G12: 473000 | I12: 6718 | J12: 81 | K12: 91
A13: tt9764362 | B13: The Menu | C13: 107 | D13: R | E13: 44883 | G13: 448000 | I13: 6062 | J13: 71 | K13: 88
A14: tt9362722 | B14: Spider-Man: Across the Spider-Verse | C14: 140 | D14: PG | E14: 45079 | G14: 444000 | I14: 8445 | J14: 86 | K14: 95
A15: tt10648342 | B15: Thor: Love and Thunder | C15: 118 | D15: PG-13 | E15: 44750 | G15: 429000 | I15: 8479 | J15: 57 | K15: 63
A16: tt6791350 | B16: Guardians of the Galaxy Vol. 3 | C16: 150 | D16: PG-13 | E16: 45051 | G16: 422000 | I16: 8180 | J16: 64 | K16: 82
A17: tt10366206 | B17: John Wick: Chapter 4 | C17: 169 | D17: R | E17: 45009 | G17: 372000 | I17: 7825 | J17: 78 | K17: 94
A18: tt14230458 | B18: Poor Things | C18: 141 | D18: R | E18: 45282 | G18: 336000 | I18: 5416 | J18: 88 | K18: 92
A19: tt9114286 | B19: Black Panther: Wakanda Forever | C19: 161 | D19: PG-13 | E19: 44876 | G19: 327000 | I19: 7385 | J19: 67 | K19: 84
A20: tt10954984 | B20: Nope | C20: 130 | D20: R | E20: 44764 | G20: 296000 | I20: 4808 | J20: 77 | K20: 83
A21: tt6443346 | B21: Black Adam | C21: 125 | D21: PG-13 | E21: 44855 | G21: 290000 | I21: 6952 | J21: 41 | K21: 39
A22: tt17526714 | B22: The Substance | C22: 141 | D22: R | E22: 45555 | G22: 284000 | I22: 5872 | J22: 78 | K22: 89
... A37: tt13833688 | B37: The Whale | C37: 117 | D37: R | E37: 44916 | G37: 243000 | I37: 4615 | J37: 60 | K37: 64
A38: tt17351924 | B38: Saltburn | C38: 131 | D38: R | E38: 45282 | G38: 242000 | J38: 61 | K38: 72
A39: tt18412256 | B39: Alien: Romulus | C39: 119 | D39: R | E39: 45520 | G39: 239000 | I39: 4441 | J39: 64 | K39: 80
A40: tt17279496 | B40: Civil War | C40: 109 | D40: R | E40: 45394 | G40: 233000 | I40: 4241 | J40: 75 | K40: 81
A41: tt0439572 | B41: The Flash | C41: 144 | D41: PG-13 | E41: 45093 | G41: 231000 | I41: 4925 | J41: 55 | K41: 63
A42: tt12747748 | B42: Leave the World Behind | C42: 138 | D42: R | E42: 45268 | G42: 228000 | I42: 3169 | J42: 68 | K42: 73
A43: tt7144666 | B43: The Black Phone | C43: 103 | D43: R | E43: 44736 | G43: 224000 | I43: 5758 | J43: 65 | K43: 81
A44: tt8041270 | B44: Jurassic World: Dominion | C44: 147 | D44: PG-13 | E44: 44722 | G44: 221000 | I44: 6975 | J44: 38 | K44: 29
A45: tt9218128 | B45: Gladiator II | C45: 148 | D45: R | E45: 45618 | G45: 219000 | I45: 4324 | J45: 64 | K45: 70
A46: tt1462764 | B46: Indiana Jones and the Dial of Destiny | C46: 154 | D46: PG-13 | E46: 45107 | G46: 218000 | I46: 4086 | J46: 58 | K46: 71
A47: tt15791034 | B47: Barbarian | C47: 102 | D47: R | E47: 44813 | G47: 218000 | I47: 3156 | J47: 78 | K47: 92
A48: tt1684562 | B48: The Fall Guy | C48: 126 | D48: PG-13 | E48: 45415 | G48: 217000 | I48: 3641 | J48: 73 | K48: 82
A49: tt22022452 | B49: Inside Out 2 | C49: 96 | D49: PG | E49: 45457 | G49: 212000 | I49: 6589 | J49: 73 | K49: 91
A50: tt15474916 | B50: Smile | C50: 115 | D50: R | E50: 44834 | G50: 212000 | I50: 3990 | J50: 68 | K50: 80
A51: tt1136617 | B51: The Killer | C51: 118 | D51: R | E51: 45240 | G51: 209000 | J51: 73 | K51: 85
A52: tt13560574 | B52: X | C52: 105 | D52: R | E52: 44638 | G52: 206000 | I52: 3902 | J52: 80 | K52: 94
A53: tt3915174 | B53: Puss in Boots: The Last Wish | C53: 102 | D53: PG | E53: 44916 | G53: 201000 | I53: 8729 | J53: 73 | K53: 95
A54: tt7657566 | B54: Death on the Nile | C54: 127 | D54: PG-13 | E54: 44603 | G54: 200000 | I54: 4138 | J54: 52 | K54: 62
...

Sheet Overlooked
A1: id | B1: title | C1: duration_minutes | D1: mpa | E1: release_date | F1: imdb_rating | G1: imdb_votes | H1: TMDB_Score | I1: TMDB_Vote_Count | J1: metacritic_score | K1: RT_Tomatometer | M1: High Rating w/ Low Votes
A2: tt9362722 | B2: Spider-Man: Across the Spider-Verse | C2: 140 | D2: PG | E2: 45079 | F2: 8.5 | H2: 8.333 | J2: 86 | K2: 95 | M2: Of 100 Highest Rated and 100 Lowest Votes
A3: tt14570440 | B3: Radical | C3: 125 | D3: PG-13 | E3: 45233 | F3: 7.8 | H3: 8.322 | J3: 70 | K3: 96
A4: tt29623480 | B4: The Wild Robot | C4: 102 | D4: PG | E4: 45562 | F4: 8.2 | H4: 8.307 | J4: 85 | K4: 97
A5: tt3915174 | B5: Puss in Boots: The Last Wish | C5: 102 | D5: PG | E5: 44916 | F5: 7.8 | H5: 8.201 | J5: 73 | K5: 95 | N5: Both | S5: IMDB Rating | T5: IMDB Votes | U5: TMDB Rating | V5: TMDB Votes
A6: tt29354040 | B6: Renaissance: A Film by BeyoncÃ© | C6: 169 | D6: Not Rated | E6: 45261 | F6: 8.6 | H6: 8.2 | I6: 36 | J6: 86 | K6: 98 | N6: tt14030682 | O6: Who We Are: A Chronicle of Racism in America | P6: 117 | Q6: PG-13 | R6: 45106 | S6: 7.7 | T6: 1300 | U6: 8 | V6: 12
A7: tt28814949 | B7: Taylor Swift: The Eras Tour | C7: 169 | D7: PG-13 | E7: 45211 | F7: 8 | H7: 8.189 | J7: 82 | K7: 98 | N7: tt7600742 | O7: Hallelujah: Leonard Cohen, a Journey, a Song | P7: 118 | Q7: PG-13 | R7: 44757 | S7: 7.6 | T7: 1600 | U7: 7.5 | V7: 32
A8: tt1745960 | B8: Top Gun: Maverick | C8: 130 | D8: PG-13 | E8: 44708 | F8: 8.2 | H8: 8.152 | J8: 78 | K8: 96
A9: tt15239678 | B9: Dune: Part Two | C9: 166 | D9: PG-13 | E9: 45352 | F9: 8.5 | H9: 8.129 | J9: 79 | K9: 92 | N9: IMDB | S9: Rating | T9: Votes
A10: tt31392609 | B10: How to Make Millions Before Grandma Dies | C10: 125 | D10: TV-PG | E10: 45548 | F10: 8 | H10: 8.12 | J10: 74 | K10: 98 | N10: tt28613536 | O10: Bob Trevino Likes It | P10: 102 | Q10: PG-13 | R10: 45779 | S10: 8.1 | T10: 389
A11: tt34956443 | B11: Ne Zha 2 | C11: 143 | D11: Not Rated | E11: 45686 | F11: 8.2 | H11: 8.118 | J11: 59 | K11: 92 | N11: tt12908150 | O11: The Life of Chuck | P11: 110 | Q11: R | R11: 45814 | S11: 7.7 | T11: 466
A12: tt14331144 | B12: Jujutsu Kaisen 0 | C12: 112 | D12: PG-13 | E12: 44638 | F12: 7.8 | H12: 8.111 | J12: 71 | K12: 98 | N12: tt14071694 | O12: Turn Every Page: The Adventures of Robert Caro and Robert Gottlieb | P12: 112 | Q12: PG | R12: 44724 | S12: 8.1 | T12: 595
A13: tt19811010 | B13: The Remarkable Life of Ibelin | C13: 103 | D13: PG-13 | E13: 45590 | F13: 8.2 | H13: 8.095 | J13: 78 | K13: 97 | N13: tt24078380 | O13: The Disappearance of Shere Hite | P13: 118 | Q13: R | R13: 45303 | S13: 7.5 | T13: 667
A14: tt4772188 | B14: Flow | C14: 85 | D14: PG | E14: 45702 | F14: 7.9 | H14: 8.089 | J14: 87 | K14: 97 | N14: tt28007064 | O14: Superboys of Malegaon | P14: 127 | Q14: PG-13 | R14: 45716 | S14: 8 | T14: 1200
A15: tt31711040 | B15: Look Back | C15: 58 | D15: 13+ | E15: 45603 | F15: 7.8 | H15: 8.062 | J15: 90 | K15: 100 | N15: tt13782428 | O15: Julia | P15: 95 | Q15: PG-13 | R15: 44711 | S15: 7.6 | T15: 1300
A16: tt4614584 | B16: Purple Hearts | C16: 122 | D16: TV-14 | E16: 44771 | H16: 8.05 | J16: 30 | K16: 32 | N16: tt16378164 | O16: The Territory | P16: 85 | Q16: PG | R16: 44897 | S16: 7.5 | T16: 1400
A17: tt23770030 | B17: Memoir of a Snail | C17: 95 | D17: R | E17: 45582 | F17: 7.8 | H17: 8.043 | J17: 81 | K17: 95 | N17: tt1461238 | O17: Kurt Vonnegut: Unstuck in Time | P17: 127 | Q17: Not Rated | R17: 44764 | S17: 7.9 | T17: 1500
A18: tt1488589 | B18: Guillermo del Toro's Pinocchio | C18: 117 | D18: PG | E18: 44904 | F18: 7.6 | H18: 8.021 | J18: 79 | K18: 27 | N18: tt13840536 | O18: It Ain't Over | P18: 99 | Q18: PG | R18: 44723 | S18: 8.2 | T18: 1600
A19: tt14030682 | B19: Who We Are: A Chronicle of Racism in America | C19: 117 | D19: PG-13 | E19: 45106 | F19: 7.7 | G19: 1300 | H19: 8 | I19: 12 | J19: 73 | K19: 98 | N19: tt4554690 | O19: The Automat | P19: 79 | Q19: TV-PG | R19: 44826 | S19: 7.8 | T19: 1700
A20: tt13429870 | B20: Robot Dreams | C20: 103 | D20: PG-13 | E20: 45450 | F20: 7.6 | H20: 8 | J20: 87 | K20: 98
A21: tt15398776 | B21: Oppenheimer | C21: 180 | D21: R | E21: 45128 | F21: 8.3 | H21: 8 | J21: 90 | K21: 93 | N21: TMDB | S21: Rating | T21: Votes
A22: tt16277242 | B22: Society of the Snow | C22: 144 | D22: R | E22: 45295 | F22: 7.8 | H22: 7.976 | J22: 72 | K22: 90 | N22: tt29354040 | O22: Renaissance: A Film by BeyoncÃ© | P22: 169 | Q22: Not Rated | R22: 45261 | S22: 8.2 | T22: 36
A23: tt8864596 | B23: Transformers One | C23: 104 | D23: PG | E23: 45555 | F23: 7.6 | H23: 7.974 | J23: 64 | K23: 89
A24: tt7599146 | B24: Sound of Freedom | C24: 131 | D24: PG-13 | E24: 45111 | F24: 7.6 | H24: 7.956 | J24: 36 | K24: 58
A25: tt8105234 | B25: Flamin' Hot | C25: 99 | D25: PG-13 | E25: 45086 | H25: 7.949 | J25: 58 | K25: 67
A26: tt10172266 | B26: Red, White & Royal Blue | C26: 118 | D26: R | E26: 45149 | H26: 7.937 | J26: 62 | K26: 75
A27: tt6791350 | B27: Guardians of the Galaxy Vol. 3 | C27: 150 | D27: PG-13 | E27: 45051 | F27: 7.9 | H27: 7.924 | J27: 64 | K27: 82
A28: tt23736044 | B28: Monster | C28: 127 | D28: PG-13 | E28: 45252 | F28: 7.8 | H28: 7.921 | J28: 79 | K28: 97
A29: tt14961016 | B29: I'm Still Here | C29: 137 | D29: PG-13 | E29: 45695 | F29: 8.4 | H29: 7.902 | J29: 85 | K29: 97
A30: tt17009348 | B30: DogMan | C30: 115 | D30: R | E30: 45387 | H30: 7.9 | J30: 45 | K30: 59
A31: tt19500164 | B31: Nimona | C31: 101 | D31: PG | E31: 45107 | F31: 7.5 | H31: 7.9 | J31: 75 | K31: 92
A32: tt16428256 | B32: Suzume | C32: 122 | D32: PG | E32: 45030 | F32: 7.6 | H32: 7.887 | J32: 77 | K32: 96
A33: tt14614892 | B33: Dragon Ball Super: Super Hero | C33: 100 | D33: PG-13 | E33: 44791 | H33: 7.879 | J33: 65 | K33: 95
A34: tt5177114 | B34: Young Woman and the Sea | C34: 129 | D34: PG | E34: 45492 | F34: 7.5 | H34: 7.864 | J34: 62 | K34: 88
A35: tt12262116 | B35: Thirteen Lives | C35: 147 | D35: PG-13 | E35: 44778 | F35: 7.8 | H35: 7.847 | J35: 66 | K35: 85
A36: tt11068094 | B36: White Bird | C36: 121 | D36: PG-13 | E36: 45569 | H36: 7.825 | J36: 54 | K36: 76
A37: tt15301048 | B37: Argentina, 1985 | C37: 140 | D37: R | E37: 44855 | F37: 7.6 | H37: 7.819 | J37: 78 | K37: 96
A38: tt25470468 | B38: Beyond Utopia | C38: 115 | D38: PG-13 | E38: 45258 | F38: 7.9 | H38: 7.8 | J38: 85 | K38: 100
A39: tt5012320 | B39: Out of My Mind | C39: 102 | D39: TV-PG | E39: 45618 | H39: 7.8 | J39: 73 | K39: 100
A40: tt14225838 | B40: Io Capitano | C40: 121 | D40: Not Rated | E40: 45176 | F40: 7.6 | H40: 7.798 | J40: 79 | K40: 96
...
